  File .py:198:SB
--------------------------------------------------------------------
Last Page: chrome://new-tab-page/
 Duration: 923.08s
  Browser: Chrome 135.0.7049.96 / headless
   Driver: chromedriver 135.0.7049.95
Timestamp: 1745088200  (Unix Timestamp)
     Date: Sunday, 20 April 2025
     Time: 1:43:20 AM  (WIB, UTC+07:00)
--------------------------------------------------------------------
Traceback:
  File "/opt/anaconda3/lib/python3.11/site-packages/IPython/core/interactiveshell.py", line 3506, in run_code
    await eval(code_obj, self.user_global_ns, self.user_ns)
  File "/var/folders/tm/cwfh2g6100d3b3h4503ydz2h0000gn/T/ipykernel_9201/3070103275.py", line 50, in <module>
    final_processed_df = pd.concat([
                                   ^
  File "/var/folders/tm/cwfh2g6100d3b3h4503ydz2h0000gn/T/ipykernel_9201/3070103275.py", line 51, in <listcomp>
    upload_pdf_and_generate_summary(sb=sb, df=row, # Pass the row (Series)
  File "/var/folders/tm/cwfh2g6100d3b3h4503ydz2h0000gn/T/ipykernel_9201/948708492.py", line 244, in upload_pdf_and_generate_summary
    sb.uc_open(link)
  File "/opt/anaconda3/lib/python3.11/site-packages/seleniumbase/core/browser_launcher.py", line 5402, in <lambda>
    driver.uc_open = lambda url: uc_open(driver, url)
                                 ^^^^^^^^^^^^^^^^^^^^
  File "/opt/anaconda3/lib/python3.11/site-packages/seleniumbase/core/browser_launcher.py", line 462, in uc_open
    js_utils.call_me_later(driver, script, 5)
  File "/opt/anaconda3/lib/python3.11/site-packages/seleniumbase/fixtures/js_utils.py", line 369, in call_me_later
    execute_script(driver, "window.setTimeout(%s, %s);" % (call, ms))
  File "/opt/anaconda3/lib/python3.11/site-packages/seleniumbase/fixtures/js_utils.py", line 20, in execute_script
    return driver.execute_script(script, *args, **kwargs)
           ^^^^^^^^^^^^^^^^^^^^^^^^^^^^^^^^^^^^^^^^^^^^^^
  File "/opt/anaconda3/lib/python3.11/site-packages/selenium/webdriver/remote/webdriver.py", line 528, in execute_script
    return self.execute(command, {"script": script, "args": converted_args})["value"]
           ^^^^^^^^^^^^^^^^^^^^^^^^^^^^^^^^^^^^^^^^^^^^^^^^^^^^^^^^^^^^^^^^^
  File "/opt/anaconda3/lib/python3.11/site-packages/selenium/webdriver/remote/webdriver.py", line 427, in execute
    response = self.command_executor.execute(driver_command, params)
               ^^^^^^^^^^^^^^^^^^^^^^^^^^^^^^^^^^^^^^^^^^^^^^^^^^^^^
  File "/opt/anaconda3/lib/python3.11/site-packages/selenium/webdriver/remote/remote_connection.py", line 404, in execute
    return self._request(command_info[0], url, body=data)
           ^^^^^^^^^^^^^^^^^^^^^^^^^^^^^^^^^^^^^^^^^^^^^^
  File "/opt/anaconda3/lib/python3.11/site-packages/selenium/webdriver/remote/remote_connection.py", line 428, in _request
    response = self._conn.request(method, url, body=body, headers=headers, timeout=self._client_config.timeout)
               ^^^^^^^^^^^^^^^^^^^^^^^^^^^^^^^^^^^^^^^^^^^^^^^^^^^^^^^^^^^^^^^^^^^^^^^^^^^^^^^^^^^^^^^^^^^^^^^^
  File "/opt/anaconda3/lib/python3.11/site-packages/urllib3/_request_methods.py", line 118, in request
    return self.request_encode_body(
           ^^^^^^^^^^^^^^^^^^^^^^^^^
  File "/opt/anaconda3/lib/python3.11/site-packages/urllib3/_request_methods.py", line 217, in request_encode_body
    return self.urlopen(method, url, **extra_kw)
           ^^^^^^^^^^^^^^^^^^^^^^^^^^^^^^^^^^^^^
  File "/opt/anaconda3/lib/python3.11/site-packages/urllib3/poolmanager.py", line 443, in urlopen
    response = conn.urlopen(method, u.request_uri, **kw)
               ^^^^^^^^^^^^^^^^^^^^^^^^^^^^^^^^^^^^^^^^^
  File "/opt/anaconda3/lib/python3.11/site-packages/urllib3/connectionpool.py", line 875, in urlopen
    return self.urlopen(
           ^^^^^^^^^^^^^
  File "/opt/anaconda3/lib/python3.11/site-packages/urllib3/connectionpool.py", line 875, in urlopen
    return self.urlopen(
           ^^^^^^^^^^^^^
  File "/opt/anaconda3/lib/python3.11/site-packages/urllib3/connectionpool.py", line 875, in urlopen
    return self.urlopen(
           ^^^^^^^^^^^^^
  File "/opt/anaconda3/lib/python3.11/site-packages/urllib3/connectionpool.py", line 845, in urlopen
    retries = retries.increment(
              ^^^^^^^^^^^^^^^^^^
  File "/opt/anaconda3/lib/python3.11/site-packages/urllib3/util/retry.py", line 515, in increment
    raise MaxRetryError(_pool, url, reason) from reason  # type: ignore[arg-type]
    ^^^^^^^^^^^^^^^^^^^^^^^^^^^^^^^^^^^^^^^^^^^^^^^^^^^
Exception: HTTPConnectionPool(host='localhost', port=64075): Max retries exceeded with url: /session/b004618fbf3a3f42d340bacff6a6072a/execute/sync (Caused by NewConnectionError('<urllib3.connection.HTTPConnection object at 0x1517b4b90>: Failed to establish a new connection: [Errno 61] Connection refused'))